{
 "cells": [
  {
   "cell_type": "code",
   "execution_count": 1,
   "id": "7c1c5192",
   "metadata": {},
   "outputs": [],
   "source": [
    "import pandas as pd\n",
    "import time, os\n",
    "import subprocess"
   ]
  },
  {
   "cell_type": "code",
   "execution_count": 2,
   "id": "b4865751",
   "metadata": {},
   "outputs": [],
   "source": [
    "bandwidth = range(10, 51, 10) # mb\n",
    "RTT = range(10, 51, 10) # ms\n",
    "reno_num = range(1, 17, 6)\n",
    "bbr_num = range(1, 17, 6)\n",
    "\n",
    "queues = [1, 2, 4, 8, 16, 32, 64]\n",
    "q = 1\n"
   ]
  },
  {
   "cell_type": "markdown",
   "id": "6db4c2d9",
   "metadata": {},
   "source": [
    "### total experiment time (hours)"
   ]
  },
  {
   "cell_type": "code",
   "execution_count": 3,
   "id": "7748699e",
   "metadata": {},
   "outputs": [
    {
     "data": {
      "text/plain": [
       "26.25"
      ]
     },
     "execution_count": 3,
     "metadata": {},
     "output_type": "execute_result"
    }
   ],
   "source": [
    "len(bandwidth) * len(RTT) * len(reno_num) * len(bbr_num) * len(queues) * 60 / 3600"
   ]
  },
  {
   "cell_type": "markdown",
   "id": "1091e0aa",
   "metadata": {},
   "source": [
    "### execute the experiment"
   ]
  },
  {
   "cell_type": "code",
   "execution_count": 4,
   "id": "822c3141",
   "metadata": {
    "scrolled": true
   },
   "outputs": [
    {
     "name": "stdout",
     "output_type": "stream",
     "text": [
      "hostname: sender.qyl-project1.ch-geni-net.geni.uchicago.edu\n",
      "lsof: unacceptable port specification in: -i :\n",
      "lsof 4.89\n",
      " latest revision: ftp://lsof.itap.purdue.edu/pub/tools/unix/lsof/\n",
      " latest FAQ: ftp://lsof.itap.purdue.edu/pub/tools/unix/lsof/FAQ\n",
      " latest man page: ftp://lsof.itap.purdue.edu/pub/tools/unix/lsof/lsof_man\n",
      " usage: [-?abhKlnNoOPRtUvVX] [+|-c c] [+|-d s] [+D D] [+|-E] [+|-e s] [+|-f[gG]]\n",
      " [-F [f]] [-g [s]] [-i [i]] [+|-L [l]] [+m [m]] [+|-M] [-o [o]] [-p s]\n",
      " [+|-r [t]] [-s [p:s]] [-S [t]] [-T [t]] [-u s] [+|-w] [-x [fl]] [--] [names]\n",
      "Use the ``-h'' option to get more help information.\n",
      "\n",
      "Usage:\n",
      " kill [options] <pid> [...]\n",
      "\n",
      "Options:\n",
      " <pid> [...]            send signal to every <pid> listed\n",
      " -<signal>, -s, --signal <signal>\n",
      "                        specify the <signal> to be sent\n",
      " -l, --list=[<signal>]  list all signal names, or convert one to a name\n",
      " -L, --table            list all signal names in a nice table\n",
      "\n",
      " -h, --help     display this help and exit\n",
      " -V, --version  output version information and exit\n",
      "\n",
      "For more details see kill(1).\n",
      "lsof: unacceptable port specification in: -i :\n",
      "lsof 4.89\n",
      " latest revision: ftp://lsof.itap.purdue.edu/pub/tools/unix/lsof/\n",
      " latest FAQ: ftp://lsof.itap.purdue.edu/pub/tools/unix/lsof/FAQ\n",
      " latest man page: ftp://lsof.itap.purdue.edu/pub/tools/unix/lsof/lsof_man\n",
      " usage: [-?abhKlnNoOPRtUvVX] [+|-c c] [+|-d s] [+D D] [+|-E] [+|-e s] [+|-f[gG]]\n",
      " [-F [f]] [-g [s]] [-i [i]] [+|-L [l]] [+m [m]] [+|-M] [-o [o]] [-p s]\n",
      " [+|-r [t]] [-s [p:s]] [-S [t]] [-T [t]] [-u s] [+|-w] [-x [fl]] [--] [names]\n",
      "Use the ``-h'' option to get more help information.\n",
      "\n",
      "Usage:\n",
      " kill [options] <pid> [...]\n",
      "\n",
      "Options:\n",
      " <pid> [...]            send signal to every <pid> listed\n",
      " -<signal>, -s, --signal <signal>\n",
      "                        specify the <signal> to be sent\n",
      " -l, --list=[<signal>]  list all signal names, or convert one to a name\n",
      " -L, --table            list all signal names in a nice table\n",
      "\n",
      " -h, --help     display this help and exit\n",
      " -V, --version  output version information and exit\n",
      "\n",
      "For more details see kill(1).\n",
      "RTNETLINK answers: No such file or directory\n",
      "Cannot find device \"eth2\"\n"
     ]
    }
   ],
   "source": [
    "!source testbed_setup.sh\n",
    "!source exp1_kill.sh"
   ]
  },
  {
   "cell_type": "code",
   "execution_count": null,
   "id": "5fdf64cd",
   "metadata": {},
   "outputs": [
    {
     "name": "stdout",
     "output_type": "stream",
     "text": [
      "exp: 1 1 1 10 10 completed\n"
     ]
    },
    {
     "name": "stderr",
     "output_type": "stream",
     "text": [
      "RTNETLINK answers: File exists\n"
     ]
    },
    {
     "name": "stdout",
     "output_type": "stream",
     "text": [
      "exp: 1 7 1 10 10 completed\n",
      "exp: 1 13 1 10 10 completed\n",
      "exp: 1 1 7 10 10 completed\n",
      "exp: 1 7 7 10 10 completed\n",
      "exp: 1 13 7 10 10 completed\n",
      "exp: 1 1 13 10 10 completed\n",
      "exp: 1 7 13 10 10 completed\n",
      "exp: 1 13 13 10 10 completed\n",
      "exp: 1 1 1 10 20 completed\n",
      "exp: 1 7 1 10 20 completed\n",
      "exp: 1 13 1 10 20 completed\n"
     ]
    },
    {
     "name": "stderr",
     "output_type": "stream",
     "text": [
      "ERROR:root:Internal Python error in the inspect module.\n",
      "Below is the traceback from this internal error.\n",
      "\n",
      "ERROR:root:Internal Python error in the inspect module.\n",
      "Below is the traceback from this internal error.\n",
      "\n"
     ]
    },
    {
     "name": "stdout",
     "output_type": "stream",
     "text": [
      "Traceback (most recent call last):\n",
      "  File \"/users/qil77/anaconda3/lib/python3.9/site-packages/IPython/core/interactiveshell.py\", line 3444, in run_code\n",
      "    exec(code_obj, self.user_global_ns, self.user_ns)\n",
      "  File \"/tmp/ipykernel_24259/3444484004.py\", line 9, in <module>\n",
      "    time.sleep(10)\n",
      "KeyboardInterrupt\n",
      "\n",
      "During handling of the above exception, another exception occurred:\n",
      "\n",
      "Traceback (most recent call last):\n",
      "  File \"/users/qil77/anaconda3/lib/python3.9/site-packages/IPython/core/interactiveshell.py\", line 2064, in showtraceback\n",
      "    stb = value._render_traceback_()\n",
      "AttributeError: 'KeyboardInterrupt' object has no attribute '_render_traceback_'\n",
      "\n",
      "During handling of the above exception, another exception occurred:\n",
      "\n",
      "Traceback (most recent call last):\n",
      "  File \"/users/qil77/anaconda3/lib/python3.9/site-packages/IPython/core/ultratb.py\", line 1101, in get_records\n",
      "    return _fixed_getinnerframes(etb, number_of_lines_of_context, tb_offset)\n",
      "  File \"/users/qil77/anaconda3/lib/python3.9/site-packages/IPython/core/ultratb.py\", line 248, in wrapped\n",
      "    return f(*args, **kwargs)\n",
      "  File \"/users/qil77/anaconda3/lib/python3.9/site-packages/IPython/core/ultratb.py\", line 281, in _fixed_getinnerframes\n",
      "    records = fix_frame_records_filenames(inspect.getinnerframes(etb, context))\n",
      "  File \"/users/qil77/anaconda3/lib/python3.9/inspect.py\", line 1541, in getinnerframes\n",
      "    frameinfo = (tb.tb_frame,) + getframeinfo(tb, context)\n",
      "  File \"/users/qil77/anaconda3/lib/python3.9/inspect.py\", line 1499, in getframeinfo\n",
      "    filename = getsourcefile(frame) or getfile(frame)\n",
      "  File \"/users/qil77/anaconda3/lib/python3.9/inspect.py\", line 709, in getsourcefile\n",
      "    if getattr(getmodule(object, filename), '__loader__', None) is not None:\n",
      "  File \"/users/qil77/anaconda3/lib/python3.9/inspect.py\", line 755, in getmodule\n",
      "    os.path.realpath(f)] = module.__name__\n",
      "  File \"/users/qil77/anaconda3/lib/python3.9/posixpath.py\", line 392, in realpath\n",
      "    path, ok = _joinrealpath(filename[:0], filename, {})\n",
      "  File \"/users/qil77/anaconda3/lib/python3.9/posixpath.py\", line 426, in _joinrealpath\n",
      "    if not islink(newpath):\n",
      "  File \"/users/qil77/anaconda3/lib/python3.9/posixpath.py\", line 167, in islink\n",
      "    st = os.lstat(path)\n",
      "KeyboardInterrupt\n",
      "Traceback (most recent call last):\n",
      "  File \"/users/qil77/anaconda3/lib/python3.9/site-packages/IPython/core/interactiveshell.py\", line 3444, in run_code\n",
      "    exec(code_obj, self.user_global_ns, self.user_ns)\n",
      "  File \"/tmp/ipykernel_24259/3444484004.py\", line 9, in <module>\n",
      "    time.sleep(10)\n",
      "KeyboardInterrupt\n",
      "\n",
      "During handling of the above exception, another exception occurred:\n",
      "\n",
      "Traceback (most recent call last):\n",
      "  File \"/users/qil77/anaconda3/lib/python3.9/site-packages/IPython/core/interactiveshell.py\", line 2064, in showtraceback\n",
      "    stb = value._render_traceback_()\n",
      "AttributeError: 'KeyboardInterrupt' object has no attribute '_render_traceback_'\n",
      "\n",
      "During handling of the above exception, another exception occurred:\n",
      "\n",
      "Traceback (most recent call last):\n",
      "  File \"/users/qil77/anaconda3/lib/python3.9/site-packages/IPython/core/interactiveshell.py\", line 3364, in run_ast_nodes\n",
      "    if (await self.run_code(code, result,  async_=asy)):\n",
      "  File \"/users/qil77/anaconda3/lib/python3.9/site-packages/IPython/core/interactiveshell.py\", line 3461, in run_code\n",
      "    self.showtraceback(running_compiled_code=True)\n",
      "  File \"/users/qil77/anaconda3/lib/python3.9/site-packages/IPython/core/interactiveshell.py\", line 2066, in showtraceback\n",
      "    stb = self.InteractiveTB.structured_traceback(etype,\n",
      "  File \"/users/qil77/anaconda3/lib/python3.9/site-packages/IPython/core/ultratb.py\", line 1367, in structured_traceback\n",
      "    return FormattedTB.structured_traceback(\n",
      "  File \"/users/qil77/anaconda3/lib/python3.9/site-packages/IPython/core/ultratb.py\", line 1267, in structured_traceback\n",
      "    return VerboseTB.structured_traceback(\n",
      "  File \"/users/qil77/anaconda3/lib/python3.9/site-packages/IPython/core/ultratb.py\", line 1124, in structured_traceback\n",
      "    formatted_exception = self.format_exception_as_a_whole(etype, evalue, etb, number_of_lines_of_context,\n",
      "  File \"/users/qil77/anaconda3/lib/python3.9/site-packages/IPython/core/ultratb.py\", line 1082, in format_exception_as_a_whole\n",
      "    last_unique, recursion_repeat = find_recursion(orig_etype, evalue, records)\n",
      "  File \"/users/qil77/anaconda3/lib/python3.9/site-packages/IPython/core/ultratb.py\", line 382, in find_recursion\n",
      "    return len(records), 0\n",
      "TypeError: object of type 'NoneType' has no len()\n",
      "\n",
      "During handling of the above exception, another exception occurred:\n",
      "\n",
      "Traceback (most recent call last):\n",
      "  File \"/users/qil77/anaconda3/lib/python3.9/site-packages/IPython/core/interactiveshell.py\", line 2064, in showtraceback\n",
      "    stb = value._render_traceback_()\n",
      "AttributeError: 'TypeError' object has no attribute '_render_traceback_'\n",
      "\n",
      "During handling of the above exception, another exception occurred:\n",
      "\n",
      "Traceback (most recent call last):\n",
      "  File \"/users/qil77/anaconda3/lib/python3.9/site-packages/IPython/core/ultratb.py\", line 1101, in get_records\n",
      "    return _fixed_getinnerframes(etb, number_of_lines_of_context, tb_offset)\n",
      "  File \"/users/qil77/anaconda3/lib/python3.9/site-packages/IPython/core/ultratb.py\", line 248, in wrapped\n",
      "    return f(*args, **kwargs)\n",
      "  File \"/users/qil77/anaconda3/lib/python3.9/site-packages/IPython/core/ultratb.py\", line 281, in _fixed_getinnerframes\n",
      "    records = fix_frame_records_filenames(inspect.getinnerframes(etb, context))\n",
      "  File \"/users/qil77/anaconda3/lib/python3.9/inspect.py\", line 1541, in getinnerframes\n",
      "    frameinfo = (tb.tb_frame,) + getframeinfo(tb, context)\n",
      "  File \"/users/qil77/anaconda3/lib/python3.9/inspect.py\", line 1499, in getframeinfo\n",
      "    filename = getsourcefile(frame) or getfile(frame)\n",
      "  File \"/users/qil77/anaconda3/lib/python3.9/inspect.py\", line 709, in getsourcefile\n",
      "    if getattr(getmodule(object, filename), '__loader__', None) is not None:\n",
      "  File \"/users/qil77/anaconda3/lib/python3.9/inspect.py\", line 755, in getmodule\n",
      "    os.path.realpath(f)] = module.__name__\n",
      "  File \"/users/qil77/anaconda3/lib/python3.9/posixpath.py\", line 392, in realpath\n",
      "    path, ok = _joinrealpath(filename[:0], filename, {})\n",
      "  File \"/users/qil77/anaconda3/lib/python3.9/posixpath.py\", line 426, in _joinrealpath\n",
      "    if not islink(newpath):\n",
      "  File \"/users/qil77/anaconda3/lib/python3.9/posixpath.py\", line 167, in islink\n",
      "    st = os.lstat(path)\n",
      "KeyboardInterrupt\n"
     ]
    },
    {
     "name": "stderr",
     "output_type": "stream",
     "text": [
      "ERROR:root:Internal Python error in the inspect module.\n",
      "Below is the traceback from this internal error.\n",
      "\n",
      "--- Logging error ---\n",
      "Traceback (most recent call last):\n",
      "  File \"/users/qil77/anaconda3/lib/python3.9/site-packages/IPython/core/interactiveshell.py\", line 3444, in run_code\n",
      "    exec(code_obj, self.user_global_ns, self.user_ns)\n",
      "  File \"/tmp/ipykernel_24259/3444484004.py\", line 9, in <module>\n",
      "    time.sleep(10)\n",
      "KeyboardInterrupt\n",
      "\n",
      "During handling of the above exception, another exception occurred:\n",
      "\n",
      "Traceback (most recent call last):\n",
      "  File \"/users/qil77/anaconda3/lib/python3.9/site-packages/IPython/core/interactiveshell.py\", line 2064, in showtraceback\n",
      "    stb = value._render_traceback_()\n",
      "AttributeError: 'KeyboardInterrupt' object has no attribute '_render_traceback_'\n",
      "\n",
      "During handling of the above exception, another exception occurred:\n",
      "\n",
      "Traceback (most recent call last):\n",
      "  File \"/users/qil77/anaconda3/lib/python3.9/site-packages/IPython/core/interactiveshell.py\", line 3364, in run_ast_nodes\n",
      "    if (await self.run_code(code, result,  async_=asy)):\n",
      "  File \"/users/qil77/anaconda3/lib/python3.9/site-packages/IPython/core/interactiveshell.py\", line 3461, in run_code\n",
      "    self.showtraceback(running_compiled_code=True)\n",
      "  File \"/users/qil77/anaconda3/lib/python3.9/site-packages/IPython/core/interactiveshell.py\", line 2066, in showtraceback\n",
      "    stb = self.InteractiveTB.structured_traceback(etype,\n",
      "  File \"/users/qil77/anaconda3/lib/python3.9/site-packages/IPython/core/ultratb.py\", line 1367, in structured_traceback\n",
      "    return FormattedTB.structured_traceback(\n",
      "  File \"/users/qil77/anaconda3/lib/python3.9/site-packages/IPython/core/ultratb.py\", line 1267, in structured_traceback\n",
      "    return VerboseTB.structured_traceback(\n",
      "  File \"/users/qil77/anaconda3/lib/python3.9/site-packages/IPython/core/ultratb.py\", line 1124, in structured_traceback\n",
      "    formatted_exception = self.format_exception_as_a_whole(etype, evalue, etb, number_of_lines_of_context,\n",
      "  File \"/users/qil77/anaconda3/lib/python3.9/site-packages/IPython/core/ultratb.py\", line 1082, in format_exception_as_a_whole\n",
      "    last_unique, recursion_repeat = find_recursion(orig_etype, evalue, records)\n",
      "  File \"/users/qil77/anaconda3/lib/python3.9/site-packages/IPython/core/ultratb.py\", line 382, in find_recursion\n",
      "    return len(records), 0\n",
      "TypeError: object of type 'NoneType' has no len()\n",
      "\n",
      "During handling of the above exception, another exception occurred:\n",
      "\n",
      "Traceback (most recent call last):\n",
      "  File \"/users/qil77/anaconda3/lib/python3.9/site-packages/IPython/core/interactiveshell.py\", line 2064, in showtraceback\n",
      "    stb = value._render_traceback_()\n",
      "AttributeError: 'TypeError' object has no attribute '_render_traceback_'\n",
      "\n",
      "During handling of the above exception, another exception occurred:\n",
      "\n",
      "Traceback (most recent call last):\n",
      "  File \"/users/qil77/anaconda3/lib/python3.9/site-packages/IPython/core/interactiveshell.py\", line 2947, in _run_cell\n",
      "    return runner(coro)\n",
      "  File \"/users/qil77/anaconda3/lib/python3.9/site-packages/IPython/core/async_helpers.py\", line 68, in _pseudo_sync_runner\n",
      "    coro.send(None)\n",
      "  File \"/users/qil77/anaconda3/lib/python3.9/site-packages/IPython/core/interactiveshell.py\", line 3172, in run_cell_async\n",
      "    has_raised = await self.run_ast_nodes(code_ast.body, cell_name,\n",
      "  File \"/users/qil77/anaconda3/lib/python3.9/site-packages/IPython/core/interactiveshell.py\", line 3383, in run_ast_nodes\n",
      "    self.showtraceback()\n",
      "  File \"/users/qil77/anaconda3/lib/python3.9/site-packages/IPython/core/interactiveshell.py\", line 2066, in showtraceback\n",
      "    stb = self.InteractiveTB.structured_traceback(etype,\n",
      "  File \"/users/qil77/anaconda3/lib/python3.9/site-packages/IPython/core/ultratb.py\", line 1367, in structured_traceback\n",
      "    return FormattedTB.structured_traceback(\n",
      "  File \"/users/qil77/anaconda3/lib/python3.9/site-packages/IPython/core/ultratb.py\", line 1267, in structured_traceback\n",
      "    return VerboseTB.structured_traceback(\n",
      "  File \"/users/qil77/anaconda3/lib/python3.9/site-packages/IPython/core/ultratb.py\", line 1142, in structured_traceback\n",
      "    formatted_exceptions += self.format_exception_as_a_whole(etype, evalue, etb, lines_of_context,\n",
      "  File \"/users/qil77/anaconda3/lib/python3.9/site-packages/IPython/core/ultratb.py\", line 1082, in format_exception_as_a_whole\n",
      "    last_unique, recursion_repeat = find_recursion(orig_etype, evalue, records)\n",
      "  File \"/users/qil77/anaconda3/lib/python3.9/site-packages/IPython/core/ultratb.py\", line 382, in find_recursion\n",
      "    return len(records), 0\n",
      "TypeError: object of type 'NoneType' has no len()\n",
      "\n",
      "During handling of the above exception, another exception occurred:\n",
      "\n",
      "Traceback (most recent call last):\n",
      "  File \"/users/qil77/anaconda3/lib/python3.9/site-packages/IPython/core/interactiveshell.py\", line 2064, in showtraceback\n",
      "    stb = value._render_traceback_()\n",
      "AttributeError: 'TypeError' object has no attribute '_render_traceback_'\n",
      "\n",
      "During handling of the above exception, another exception occurred:\n",
      "\n",
      "Traceback (most recent call last):\n",
      "  File \"/users/qil77/anaconda3/lib/python3.9/site-packages/ipykernel/kernelbase.py\", line 353, in dispatch_shell\n",
      "    await result\n"
     ]
    },
    {
     "name": "stdout",
     "output_type": "stream",
     "text": [
      "Traceback (most recent call last):\n",
      "  File \"/users/qil77/anaconda3/lib/python3.9/site-packages/IPython/core/interactiveshell.py\", line 3444, in run_code\n",
      "    exec(code_obj, self.user_global_ns, self.user_ns)\n",
      "  File \"/tmp/ipykernel_24259/3444484004.py\", line 9, in <module>\n",
      "    time.sleep(10)\n",
      "KeyboardInterrupt\n",
      "\n",
      "During handling of the above exception, another exception occurred:\n",
      "\n",
      "Traceback (most recent call last):\n",
      "  File \"/users/qil77/anaconda3/lib/python3.9/site-packages/IPython/core/interactiveshell.py\", line 2064, in showtraceback\n",
      "    stb = value._render_traceback_()\n",
      "AttributeError: 'KeyboardInterrupt' object has no attribute '_render_traceback_'\n",
      "\n",
      "During handling of the above exception, another exception occurred:\n",
      "\n",
      "Traceback (most recent call last):\n",
      "  File \"/users/qil77/anaconda3/lib/python3.9/site-packages/IPython/core/interactiveshell.py\", line 3364, in run_ast_nodes\n",
      "    if (await self.run_code(code, result,  async_=asy)):\n",
      "  File \"/users/qil77/anaconda3/lib/python3.9/site-packages/IPython/core/interactiveshell.py\", line 3461, in run_code\n",
      "    self.showtraceback(running_compiled_code=True)\n",
      "  File \"/users/qil77/anaconda3/lib/python3.9/site-packages/IPython/core/interactiveshell.py\", line 2066, in showtraceback\n",
      "    stb = self.InteractiveTB.structured_traceback(etype,\n",
      "  File \"/users/qil77/anaconda3/lib/python3.9/site-packages/IPython/core/ultratb.py\", line 1367, in structured_traceback\n",
      "    return FormattedTB.structured_traceback(\n",
      "  File \"/users/qil77/anaconda3/lib/python3.9/site-packages/IPython/core/ultratb.py\", line 1267, in structured_traceback\n",
      "    return VerboseTB.structured_traceback(\n",
      "  File \"/users/qil77/anaconda3/lib/python3.9/site-packages/IPython/core/ultratb.py\", line 1124, in structured_traceback\n",
      "    formatted_exception = self.format_exception_as_a_whole(etype, evalue, etb, number_of_lines_of_context,\n",
      "  File \"/users/qil77/anaconda3/lib/python3.9/site-packages/IPython/core/ultratb.py\", line 1082, in format_exception_as_a_whole\n",
      "    last_unique, recursion_repeat = find_recursion(orig_etype, evalue, records)\n",
      "  File \"/users/qil77/anaconda3/lib/python3.9/site-packages/IPython/core/ultratb.py\", line 382, in find_recursion\n",
      "    return len(records), 0\n",
      "TypeError: object of type 'NoneType' has no len()\n",
      "\n",
      "During handling of the above exception, another exception occurred:\n",
      "\n",
      "Traceback (most recent call last):\n",
      "  File \"/users/qil77/anaconda3/lib/python3.9/site-packages/IPython/core/interactiveshell.py\", line 2064, in showtraceback\n",
      "    stb = value._render_traceback_()\n",
      "AttributeError: 'TypeError' object has no attribute '_render_traceback_'\n",
      "\n",
      "During handling of the above exception, another exception occurred:\n",
      "\n",
      "Traceback (most recent call last):\n",
      "  File \"/users/qil77/anaconda3/lib/python3.9/site-packages/IPython/core/interactiveshell.py\", line 2947, in _run_cell\n",
      "    return runner(coro)\n",
      "  File \"/users/qil77/anaconda3/lib/python3.9/site-packages/IPython/core/async_helpers.py\", line 68, in _pseudo_sync_runner\n",
      "    coro.send(None)\n",
      "  File \"/users/qil77/anaconda3/lib/python3.9/site-packages/IPython/core/interactiveshell.py\", line 3172, in run_cell_async\n",
      "    has_raised = await self.run_ast_nodes(code_ast.body, cell_name,\n",
      "  File \"/users/qil77/anaconda3/lib/python3.9/site-packages/IPython/core/interactiveshell.py\", line 3383, in run_ast_nodes\n",
      "    self.showtraceback()\n",
      "  File \"/users/qil77/anaconda3/lib/python3.9/site-packages/IPython/core/interactiveshell.py\", line 2066, in showtraceback\n",
      "    stb = self.InteractiveTB.structured_traceback(etype,\n",
      "  File \"/users/qil77/anaconda3/lib/python3.9/site-packages/IPython/core/ultratb.py\", line 1367, in structured_traceback\n",
      "    return FormattedTB.structured_traceback(\n",
      "  File \"/users/qil77/anaconda3/lib/python3.9/site-packages/IPython/core/ultratb.py\", line 1267, in structured_traceback\n",
      "    return VerboseTB.structured_traceback(\n",
      "  File \"/users/qil77/anaconda3/lib/python3.9/site-packages/IPython/core/ultratb.py\", line 1142, in structured_traceback\n",
      "    formatted_exceptions += self.format_exception_as_a_whole(etype, evalue, etb, lines_of_context,\n",
      "  File \"/users/qil77/anaconda3/lib/python3.9/site-packages/IPython/core/ultratb.py\", line 1082, in format_exception_as_a_whole\n",
      "    last_unique, recursion_repeat = find_recursion(orig_etype, evalue, records)\n",
      "  File \"/users/qil77/anaconda3/lib/python3.9/site-packages/IPython/core/ultratb.py\", line 382, in find_recursion\n",
      "    return len(records), 0\n",
      "TypeError: object of type 'NoneType' has no len()\n",
      "\n",
      "During handling of the above exception, another exception occurred:\n",
      "\n",
      "Traceback (most recent call last):\n",
      "  File \"/users/qil77/anaconda3/lib/python3.9/site-packages/IPython/core/interactiveshell.py\", line 2064, in showtraceback\n",
      "    stb = value._render_traceback_()\n",
      "AttributeError: 'TypeError' object has no attribute '_render_traceback_'\n",
      "\n",
      "During handling of the above exception, another exception occurred:\n",
      "\n",
      "Traceback (most recent call last):\n",
      "  File \"/users/qil77/anaconda3/lib/python3.9/site-packages/IPython/core/ultratb.py\", line 1101, in get_records\n",
      "    return _fixed_getinnerframes(etb, number_of_lines_of_context, tb_offset)\n",
      "  File \"/users/qil77/anaconda3/lib/python3.9/site-packages/IPython/core/ultratb.py\", line 248, in wrapped\n",
      "    return f(*args, **kwargs)\n",
      "  File \"/users/qil77/anaconda3/lib/python3.9/site-packages/IPython/core/ultratb.py\", line 281, in _fixed_getinnerframes\n",
      "    records = fix_frame_records_filenames(inspect.getinnerframes(etb, context))\n",
      "  File \"/users/qil77/anaconda3/lib/python3.9/inspect.py\", line 1541, in getinnerframes\n",
      "    frameinfo = (tb.tb_frame,) + getframeinfo(tb, context)\n",
      "  File \"/users/qil77/anaconda3/lib/python3.9/inspect.py\", line 1499, in getframeinfo\n",
      "    filename = getsourcefile(frame) or getfile(frame)\n",
      "  File \"/users/qil77/anaconda3/lib/python3.9/inspect.py\", line 709, in getsourcefile\n",
      "    if getattr(getmodule(object, filename), '__loader__', None) is not None:\n",
      "  File \"/users/qil77/anaconda3/lib/python3.9/inspect.py\", line 755, in getmodule\n",
      "    os.path.realpath(f)] = module.__name__\n",
      "  File \"/users/qil77/anaconda3/lib/python3.9/posixpath.py\", line 392, in realpath\n",
      "    path, ok = _joinrealpath(filename[:0], filename, {})\n",
      "  File \"/users/qil77/anaconda3/lib/python3.9/posixpath.py\", line 425, in _joinrealpath\n",
      "    newpath = join(path, name)\n",
      "  File \"/users/qil77/anaconda3/lib/python3.9/posixpath.py\", line 83, in join\n",
      "    if b.startswith(sep):\n",
      "KeyboardInterrupt\n"
     ]
    },
    {
     "name": "stderr",
     "output_type": "stream",
     "text": [
      "  File \"/users/qil77/anaconda3/lib/python3.9/site-packages/ipykernel/kernelbase.py\", line 648, in execute_request\n",
      "    reply_content = await reply_content\n",
      "  File \"/users/qil77/anaconda3/lib/python3.9/site-packages/ipykernel/ipkernel.py\", line 353, in do_execute\n",
      "    res = shell.run_cell(code, store_history=store_history, silent=silent)\n",
      "  File \"/users/qil77/anaconda3/lib/python3.9/site-packages/ipykernel/zmqshell.py\", line 533, in run_cell\n",
      "    return super(ZMQInteractiveShell, self).run_cell(*args, **kwargs)\n",
      "  File \"/users/qil77/anaconda3/lib/python3.9/site-packages/IPython/core/interactiveshell.py\", line 2901, in run_cell\n",
      "    result = self._run_cell(\n",
      "  File \"/users/qil77/anaconda3/lib/python3.9/site-packages/IPython/core/interactiveshell.py\", line 2952, in _run_cell\n",
      "    self.showtraceback(running_compiled_code=True)\n",
      "  File \"/users/qil77/anaconda3/lib/python3.9/site-packages/IPython/core/interactiveshell.py\", line 2066, in showtraceback\n",
      "    stb = self.InteractiveTB.structured_traceback(etype,\n",
      "  File \"/users/qil77/anaconda3/lib/python3.9/site-packages/IPython/core/ultratb.py\", line 1367, in structured_traceback\n",
      "    return FormattedTB.structured_traceback(\n",
      "  File \"/users/qil77/anaconda3/lib/python3.9/site-packages/IPython/core/ultratb.py\", line 1267, in structured_traceback\n",
      "    return VerboseTB.structured_traceback(\n",
      "  File \"/users/qil77/anaconda3/lib/python3.9/site-packages/IPython/core/ultratb.py\", line 1142, in structured_traceback\n",
      "    formatted_exceptions += self.format_exception_as_a_whole(etype, evalue, etb, lines_of_context,\n",
      "  File \"/users/qil77/anaconda3/lib/python3.9/site-packages/IPython/core/ultratb.py\", line 1082, in format_exception_as_a_whole\n",
      "    last_unique, recursion_repeat = find_recursion(orig_etype, evalue, records)\n",
      "  File \"/users/qil77/anaconda3/lib/python3.9/site-packages/IPython/core/ultratb.py\", line 382, in find_recursion\n",
      "    return len(records), 0\n",
      "TypeError: object of type 'NoneType' has no len()\n",
      "\n",
      "During handling of the above exception, another exception occurred:\n",
      "\n",
      "Traceback (most recent call last):\n",
      "  File \"/users/qil77/anaconda3/lib/python3.9/logging/__init__.py\", line 1087, in emit\n",
      "    self.flush()\n",
      "  File \"/users/qil77/anaconda3/lib/python3.9/logging/__init__.py\", line 1067, in flush\n",
      "    self.stream.flush()\n",
      "OSError: [Errno 5] Input/output error\n",
      "Call stack:\n",
      "  File \"/users/qil77/anaconda3/lib/python3.9/runpy.py\", line 197, in _run_module_as_main\n",
      "    return _run_code(code, main_globals, None,\n",
      "  File \"/users/qil77/anaconda3/lib/python3.9/runpy.py\", line 87, in _run_code\n",
      "    exec(code, run_globals)\n",
      "  File \"/users/qil77/anaconda3/lib/python3.9/site-packages/ipykernel_launcher.py\", line 16, in <module>\n",
      "    app.launch_new_instance()\n",
      "  File \"/users/qil77/anaconda3/lib/python3.9/site-packages/traitlets/config/application.py\", line 846, in launch_instance\n",
      "    app.start()\n",
      "  File \"/users/qil77/anaconda3/lib/python3.9/site-packages/ipykernel/kernelapp.py\", line 677, in start\n",
      "    self.io_loop.start()\n",
      "  File \"/users/qil77/anaconda3/lib/python3.9/site-packages/tornado/platform/asyncio.py\", line 199, in start\n",
      "    self.asyncio_loop.run_forever()\n",
      "  File \"/users/qil77/anaconda3/lib/python3.9/asyncio/base_events.py\", line 596, in run_forever\n",
      "    self._run_once()\n",
      "  File \"/users/qil77/anaconda3/lib/python3.9/asyncio/base_events.py\", line 1890, in _run_once\n",
      "    handle._run()\n",
      "  File \"/users/qil77/anaconda3/lib/python3.9/asyncio/events.py\", line 80, in _run\n",
      "    self._context.run(self._callback, *self._args)\n",
      "  File \"/users/qil77/anaconda3/lib/python3.9/site-packages/ipykernel/kernelbase.py\", line 457, in dispatch_queue\n",
      "    await self.process_one()\n",
      "  File \"/users/qil77/anaconda3/lib/python3.9/site-packages/ipykernel/kernelbase.py\", line 446, in process_one\n",
      "    await dispatch(*args)\n",
      "  File \"/users/qil77/anaconda3/lib/python3.9/site-packages/ipykernel/kernelbase.py\", line 355, in dispatch_shell\n",
      "    self.log.error(\"Exception in message handler:\", exc_info=True)\n",
      "Message: 'Exception in message handler:'\n",
      "Arguments: ()\n"
     ]
    }
   ],
   "source": [
    "for bw in bandwidth:\n",
    "    for rtt in RTT:\n",
    "        for r_num in reno_num:\n",
    "            for b_num in bbr_num:\n",
    "                output = subprocess.check_output(f\"source exp1_run.sh {q} {b_num} {r_num} {bw} {rtt}\", shell=True, executable=\"/bin/bash\")\n",
    "#                 os.environ.update(line.partition('=')[::2] for line in output.split('\\0'))\n",
    "#                 !source exp1_run.sh $q $b_num $r_num $bw $rtt\n",
    "                time.sleep(65)\n",
    "                print(f'exp: {q} {b_num} {r_num} {bw} {rtt} completed')"
   ]
  },
  {
   "cell_type": "code",
   "execution_count": null,
   "id": "7e3cf503",
   "metadata": {},
   "outputs": [],
   "source": []
  }
 ],
 "metadata": {
  "kernelspec": {
   "display_name": "Python 3 (ipykernel)",
   "language": "python",
   "name": "python3"
  },
  "language_info": {
   "codemirror_mode": {
    "name": "ipython",
    "version": 3
   },
   "file_extension": ".py",
   "mimetype": "text/x-python",
   "name": "python",
   "nbconvert_exporter": "python",
   "pygments_lexer": "ipython3",
   "version": "3.9.7"
  }
 },
 "nbformat": 4,
 "nbformat_minor": 5
}
